[2.537s] Traceback (most recent call last):
  File "/usr/lib/python3/dist-packages/colcon_parallel_executor/executor/parallel.py", line 75, in execute
    loop.run_until_complete(future)
  File "/usr/lib/python3.8/asyncio/base_events.py", line 603, in run_until_complete
    self.run_forever()
  File "/usr/lib/python3.8/asyncio/base_events.py", line 570, in run_forever
    self._run_once()
  File "/usr/lib/python3.8/asyncio/base_events.py", line 1823, in _run_once
    event_list = self._selector.select(timeout)
  File "/usr/lib/python3.8/selectors.py", line 468, in select
    fd_event_list = self._selector.poll(timeout, max_ev)
KeyboardInterrupt

During handling of the above exception, another exception occurred:

Traceback (most recent call last):
  File "/usr/lib/python3/dist-packages/colcon_core/executor/__init__.py", line 91, in __call__
    rc = await self.task(*args, **kwargs)
  File "/usr/lib/python3/dist-packages/colcon_core/task/__init__.py", line 93, in __call__
    return await task_method(*args, **kwargs)
  File "/usr/lib/python3/dist-packages/colcon_ros/task/ament_python/build.py", line 102, in build
    return await extension.build(additional_hooks=additional_hooks)
  File "/usr/lib/python3/dist-packages/colcon_core/task/python/build.py", line 96, in build
    available_commands = await self._get_available_commands(
  File "/usr/lib/python3/dist-packages/colcon_core/task/python/build.py", line 194, in _get_available_commands
    output = await check_output(
  File "/usr/lib/python3/dist-packages/colcon_core/subprocess.py", line 129, in check_output
    assert not rc, f'Expected {args} to pass: {stderr_data}'
AssertionError: Expected ['/usr/bin/python3', '-W', 'ignore:setup.py install is deprecated', '-W', 'ignore:easy_install command is deprecated', 'setup.py', '--help-commands'] to pass: Traceback (most recent call last):
  File "/home/wheeltec/.local/lib/python3.8/site-packages/pkg_resources/__init__.py", line 2381, in _normalize_cached
    return _cache[filename]
KeyError: '/home/wheeltec/wheeltec_ros2/install/wheeltec_robot_msg/lib/python3.8/site-packages'

During handling of the above exception, another exception occurred:

Traceback (most recent call last):
  File "setup.py", line 1, in <module>
    from setuptools import setup
  File "/home/wheeltec/.local/lib/python3.8/site-packages/setuptools/__init__.py", line 16, in <module>
    import setuptools.version
  File "/home/wheeltec/.local/lib/python3.8/site-packages/setuptools/version.py", line 1, in <module>
    import pkg_resources
  File "/home/wheeltec/.local/lib/python3.8/site-packages/pkg_resources/__init__.py", line 3260, in <module>
    def _initialize_master_working_set():
  File "/home/wheeltec/.local/lib/python3.8/site-packages/pkg_resources/__init__.py", line 3234, in _call_aside
    f(*args, **kwargs)
  File "/home/wheeltec/.local/lib/python3.8/site-packages/pkg_resources/__init__.py", line 3272, in _initialize_master_working_set
    working_set = WorkingSet._build_master()
  File "/home/wheeltec/.local/lib/python3.8/site-packages/pkg_resources/__init__.py", line 572, in _build_master
    ws = cls()
  File "/home/wheeltec/.local/lib/python3.8/site-packages/pkg_resources/__init__.py", line 565, in __init__
    self.add_entry(entry)
  File "/home/wheeltec/.local/lib/python3.8/site-packages/pkg_resources/__init__.py", line 621, in add_entry
    for dist in find_distributions(entry, True):
  File "/home/wheeltec/.local/lib/python3.8/site-packages/pkg_resources/__init__.py", line 2067, in find_on_path
    path_item = _normalize_cached(path_item)
  File "/home/wheeltec/.local/lib/python3.8/site-packages/pkg_resources/__init__.py", line 2383, in _normalize_cached
    _cache[filename] = result = normalize_path(filename)
  File "/home/wheeltec/.local/lib/python3.8/site-packages/pkg_resources/__init__.py", line 2364, in normalize_path
    return os.path.normcase(os.path.realpath(os.path.normpath(
  File "/usr/lib/python3.8/posixpath.py", line 356, in normpath
    new_comps = []
KeyboardInterrupt

